<?xml version="1.0"?>
<robot xmlns:xacro="http://www.ros.org/wiki/xacro" name="cnav_drone">

    <xacro:macro name="inertial_box" params="mass x y z *origin">
        <inertial>
            <xacro:insert_block name="origin"/>
            <mass value="${mass}"/>
            <inertia ixx="${(1/12) * mass * (y*y+z*z)}" ixy="0.0" ixz="0.0"
                     iyy="${(1/12) * mass * (x*x+z*z)}" iyz="0.0"
                     izz="${(1/12) * mass * (x*x+y*y)}" />
        </inertial>
    </xacro:macro>

    <xacro:macro name="inertial_cylinder" params="mass length radius *origin">
        <inertial>
            <xacro:insert_block name="origin"/>
            <mass value="${mass}"/>
            <inertia ixx="${(1/12) * mass * (3*radius*radius + length*length)}" ixy="0.0" ixz="0.0"
                     iyy="${(1/12) * mass * (3*radius*radius + length*length)}" iyz="0.0"
                     izz="${(0.5) * mass * (radius*radius)}" />
        </inertial>
    </xacro:macro>

    <link name="base_footprint"/>
    <joint name="base_joint" type="fixed">
        <parent link="base_footprint"/>
        <child link="base_link"/>
        <origin xyz="0 0 0" rpy="0 0 0"/>
    </joint>

    <link name="base_link">
        <visual>
            <geometry><box size="0.2 0.2 0.05"/></geometry>
            <material name="gray"><color rgba="0.5 0.5 0.5 1.0"/></material>
        </visual>
        <collision>
            <geometry><box size="0.2 0.2 0.05"/></geometry>
        </collision>
        <xacro:inertial_box mass="1.0" x="0.2" y="0.2" z="0.05">
            <origin xyz="0 0 0" rpy="0 0 0"/>
        </xacro:inertial_box>
    </link>

    <xacro:macro name="rotor" params="prefix x_offset y_offset direction">
        <joint name="${prefix}_rotor_joint" type="continuous">
            <parent link="base_link"/>
            <child link="${prefix}_rotor"/>
            <origin xyz="${x_offset} ${y_offset} 0.03" rpy="0 0 0"/>
            <axis xyz="0 0 1"/>
        </joint>

        <link name="${prefix}_rotor">
            <visual>
                <geometry><cylinder radius="0.1" length="0.01"/></geometry>
                <material name="blue"><color rgba="0.0 0.0 1.0 1.0"/></material>
            </visual>
            <collision>
                <geometry><cylinder radius="0.1" length="0.01"/></geometry>
            </collision>
            <xacro:inertial_cylinder mass="0.05" length="0.01" radius="0.1">
                <origin xyz="0 0 0" rpy="0 0 0"/>
            </xacro:inertial_cylinder>
        </link>
    </xacro:macro>

    <xacro:rotor prefix="fl" x_offset="0.15" y_offset="0.15" direction="ccw"/>
    <xacro:rotor prefix="fr" x_offset="0.15" y_offset="-0.15" direction="cw"/>
    <xacro:rotor prefix="bl" x_offset="-0.15" y_offset="0.15" direction="cw"/>
    <xacro:rotor prefix="br" x_offset="-0.15" y_offset="-0.15" direction="ccw"/>

    <gazebo>
        <plugin filename="gz-sim-multicopter-control-system" name="gz::sim::systems::MulticopterVelocityControl">
            <robotNamespace>cnav_drone</robotNamespace>
            <commandSubTopic>cmd_vel</commandSubTopic>
            <comLinkName>base_footprint</comLinkName>
            <velocityGain>2.7 2.7 2.7</velocityGain>
            <attitudeGain>2 3 0.15</attitudeGain>
            <angularRateGain>0.4 0.52 0.18</angularRateGain>
            <maximumLinearAcceleration>2 2 2</maximumLinearAcceleration>
            
            <rotorConfiguration>
                <rotor>
                    <jointName>fl_rotor_joint</jointName>
                    <forceConstant>8.54858e-06</forceConstant>
                    <momentConstant>0.016</momentConstant>
                    <direction>1</direction>
                </rotor>
                <rotor>
                    <jointName>fr_rotor_joint</jointName>
                    <forceConstant>8.54858e-06</forceConstant>
                    <momentConstant>0.016</momentConstant>
                    <direction>-1</direction>
                </rotor>
                <rotor>
                    <jointName>bl_rotor_joint</jointName>
                    <forceConstant>8.54858e-06</forceConstant>
                    <momentConstant>0.016</momentConstant>
                    <direction>-1</direction>
                </rotor>
                <rotor>
                    <jointName>br_rotor_joint</jointName>
                    <forceConstant>8.54858e-06</forceConstant>
                    <momentConstant>0.016</momentConstant>
                    <direction>1</direction>
                </rotor>
            </rotorConfiguration>
        </plugin>

        <plugin filename="gz-sim-multicopter-motor-model-system" name="gz::sim::systems::MulticopterMotorModel">
            <robotNamespace>cnav_drone</robotNamespace>
            <jointName>fl_rotor_joint</jointName>
            <linkName>fl_rotor</linkName>
            <turningDirection>ccw</turningDirection>
            <timeConstantUp>0.0125</timeConstantUp>
            <timeConstantDown>0.025</timeConstantDown>
            <maxRotVelocity>800.0</maxRotVelocity>
            <motorConstant>8.54858e-06</motorConstant>
            <momentConstant>0.016</momentConstant>
            <commandSubTopic>command/motor_speed</commandSubTopic>
            <actuator_number>0</actuator_number>
            <rotorDragCoefficient>8.06428e-05</rotorDragCoefficient>
            <rollingMomentCoefficient>1e-06</rollingMomentCoefficient>
            <motorType>velocity</motorType>
        </plugin>

        <plugin filename="gz-sim-multicopter-motor-model-system" name="gz::sim::systems::MulticopterMotorModel">
            <robotNamespace>cnav_drone</robotNamespace>
            <jointName>fr_rotor_joint</jointName>
            <linkName>fr_rotor</linkName>
            <turningDirection>cw</turningDirection>
            <timeConstantUp>0.0125</timeConstantUp>
            <timeConstantDown>0.025</timeConstantDown>
            <maxRotVelocity>800.0</maxRotVelocity>
            <motorConstant>8.54858e-06</motorConstant>
            <momentConstant>0.016</momentConstant>
            <commandSubTopic>command/motor_speed</commandSubTopic>
            <actuator_number>1</actuator_number>
            <rotorDragCoefficient>8.06428e-05</rotorDragCoefficient>
            <rollingMomentCoefficient>1e-06</rollingMomentCoefficient>
            <motorType>velocity</motorType>
        </plugin>

        <plugin filename="gz-sim-multicopter-motor-model-system" name="gz::sim::systems::MulticopterMotorModel">
            <robotNamespace>cnav_drone</robotNamespace>
            <jointName>bl_rotor_joint</jointName>
            <linkName>bl_rotor</linkName>
            <turningDirection>cw</turningDirection>
            <timeConstantUp>0.0125</timeConstantUp>
            <timeConstantDown>0.025</timeConstantDown>
            <maxRotVelocity>800.0</maxRotVelocity>
            <motorConstant>8.54858e-06</motorConstant>
            <momentConstant>0.016</momentConstant>
            <commandSubTopic>command/motor_speed</commandSubTopic>
            <actuator_number>2</actuator_number>
            <rotorDragCoefficient>8.06428e-05</rotorDragCoefficient>
            <rollingMomentCoefficient>1e-06</rollingMomentCoefficient>
            <motorType>velocity</motorType>
        </plugin>

        <plugin filename="gz-sim-multicopter-motor-model-system" name="gz::sim::systems::MulticopterMotorModel">
            <robotNamespace>cnav_drone</robotNamespace>
            <jointName>br_rotor_joint</jointName>
            <linkName>br_rotor</linkName>
            <turningDirection>ccw</turningDirection>
            <timeConstantUp>0.0125</timeConstantUp>
            <timeConstantDown>0.025</timeConstantDown>
            <maxRotVelocity>800.0</maxRotVelocity>
            <motorConstant>8.54858e-06</motorConstant>
            <momentConstant>0.016</momentConstant>
            <commandSubTopic>command/motor_speed</commandSubTopic>
            <actuator_number>3</actuator_number>
            <rotorDragCoefficient>8.06428e-05</rotorDragCoefficient>
            <rollingMomentCoefficient>1e-06</rollingMomentCoefficient>
            <motorType>velocity</motorType>
        </plugin>
    </gazebo>
</robot>